Traceback (most recent call last):
  File "/uufs/chpc.utah.edu/common/home/u1419540/miniconda3/envs/edl_hw3/lib/python3.11/site-packages/aiohttp/client_reqrep.py", line 70, in <module>
    import cchardet as chardet
ModuleNotFoundError: No module named 'cchardet'

During handling of the above exception, another exception occurred:

Traceback (most recent call last):
  File "/uufs/chpc.utah.edu/common/home/u1419540/miniconda3/envs/edl_hw3/lib/python3.11/site-packages/transformers/utils/import_utils.py", line 1184, in _get_module
    return importlib.import_module("." + module_name, self.__name__)
           ^^^^^^^^^^^^^^^^^^^^^^^^^^^^^^^^^^^^^^^^^^^^^^^^^^^^^^^^^
  File "/uufs/chpc.utah.edu/common/home/u1419540/miniconda3/envs/edl_hw3/lib/python3.11/importlib/__init__.py", line 126, in import_module
    return _bootstrap._gcd_import(name[level:], package, level)
           ^^^^^^^^^^^^^^^^^^^^^^^^^^^^^^^^^^^^^^^^^^^^^^^^^^^^
  File "<frozen importlib._bootstrap>", line 1204, in _gcd_import
  File "<frozen importlib._bootstrap>", line 1176, in _find_and_load
  File "<frozen importlib._bootstrap>", line 1147, in _find_and_load_unlocked
  File "<frozen importlib._bootstrap>", line 690, in _load_unlocked
  File "<frozen importlib._bootstrap_external>", line 940, in exec_module
  File "<frozen importlib._bootstrap>", line 241, in _call_with_frames_removed
  File "/uufs/chpc.utah.edu/common/home/u1419540/miniconda3/envs/edl_hw3/lib/python3.11/site-packages/transformers/trainer.py", line 167, in <module>
    import datasets
  File "/uufs/chpc.utah.edu/common/home/u1419540/miniconda3/envs/edl_hw3/lib/python3.11/site-packages/datasets/__init__.py", line 22, in <module>
    from .arrow_dataset import Dataset
  File "/uufs/chpc.utah.edu/common/home/u1419540/miniconda3/envs/edl_hw3/lib/python3.11/site-packages/datasets/arrow_dataset.py", line 66, in <module>
    from .arrow_reader import ArrowReader
  File "/uufs/chpc.utah.edu/common/home/u1419540/miniconda3/envs/edl_hw3/lib/python3.11/site-packages/datasets/arrow_reader.py", line 30, in <module>
    from .download.download_config import DownloadConfig
  File "/uufs/chpc.utah.edu/common/home/u1419540/miniconda3/envs/edl_hw3/lib/python3.11/site-packages/datasets/download/__init__.py", line 10, in <module>
    from .streaming_download_manager import StreamingDownloadManager
  File "/uufs/chpc.utah.edu/common/home/u1419540/miniconda3/envs/edl_hw3/lib/python3.11/site-packages/datasets/download/streaming_download_manager.py", line 18, in <module>
    from aiohttp.client_exceptions import ClientError
  File "/uufs/chpc.utah.edu/common/home/u1419540/miniconda3/envs/edl_hw3/lib/python3.11/site-packages/aiohttp/__init__.py", line 6, in <module>
    from .client import (
  File "/uufs/chpc.utah.edu/common/home/u1419540/miniconda3/envs/edl_hw3/lib/python3.11/site-packages/aiohttp/client.py", line 59, in <module>
    from .client_reqrep import (
  File "/uufs/chpc.utah.edu/common/home/u1419540/miniconda3/envs/edl_hw3/lib/python3.11/site-packages/aiohttp/client_reqrep.py", line 72, in <module>
    import charset_normalizer as chardet  # type: ignore[no-redef]
    ^^^^^^^^^^^^^^^^^^^^^^^^^^^^^^^^^^^^
  File "/uufs/chpc.utah.edu/common/home/u1419540/miniconda3/envs/edl_hw3/lib/python3.11/site-packages/charset_normalizer/__init__.py", line 24, in <module>
    from .api import from_bytes, from_fp, from_path, is_binary
  File "/uufs/chpc.utah.edu/common/home/u1419540/miniconda3/envs/edl_hw3/lib/python3.11/site-packages/charset_normalizer/api.py", line 5, in <module>
    from .cd import (
  File "/uufs/chpc.utah.edu/common/home/u1419540/miniconda3/envs/edl_hw3/lib/python3.11/site-packages/charset_normalizer/cd.py", line 14, in <module>
    from .md import is_suspiciously_successive_range
AttributeError: partially initialized module 'charset_normalizer' has no attribute 'md__mypyc' (most likely due to a circular import)

The above exception was the direct cause of the following exception:

Traceback (most recent call last):
  File "/uufs/chpc.utah.edu/common/home/u1419540/explainable_deep_learning/a4_adaptation_to_a1/test.py", line 2, in <module>
    from transformers import AutoTokenizer, AutoModelForSequenceClassification, TrainingArguments, Trainer
  File "<frozen importlib._bootstrap>", line 1229, in _handle_fromlist
  File "/uufs/chpc.utah.edu/common/home/u1419540/miniconda3/envs/edl_hw3/lib/python3.11/site-packages/transformers/utils/import_utils.py", line 1174, in __getattr__
    module = self._get_module(self._class_to_module[name])
             ^^^^^^^^^^^^^^^^^^^^^^^^^^^^^^^^^^^^^^^^^^^^^
  File "/uufs/chpc.utah.edu/common/home/u1419540/miniconda3/envs/edl_hw3/lib/python3.11/site-packages/transformers/utils/import_utils.py", line 1186, in _get_module
    raise RuntimeError(
RuntimeError: Failed to import transformers.trainer because of the following error (look up to see its traceback):
partially initialized module 'charset_normalizer' has no attribute 'md__mypyc' (most likely due to a circular import)
