Traceback (most recent call last):
  File "/uufs/chpc.utah.edu/common/home/u1419540/miniconda3/envs/edl_hw3/lib/python3.11/site-packages/requests/compat.py", line 11, in <module>
    import chardet
ModuleNotFoundError: No module named 'chardet'

During handling of the above exception, another exception occurred:

Traceback (most recent call last):
  File "/uufs/chpc.utah.edu/common/home/u1419540/explainable_deep_learning/a4_adaptation_to_a1/train.py", line 22, in <module>
    import datasets
  File "/uufs/chpc.utah.edu/common/home/u1419540/miniconda3/envs/edl_hw3/lib/python3.11/site-packages/datasets/__init__.py", line 22, in <module>
    from .arrow_dataset import Dataset
  File "/uufs/chpc.utah.edu/common/home/u1419540/miniconda3/envs/edl_hw3/lib/python3.11/site-packages/datasets/arrow_dataset.py", line 61, in <module>
    from huggingface_hub import DatasetCard, DatasetCardData, HfApi, HfFolder
  File "/uufs/chpc.utah.edu/common/home/u1419540/miniconda3/envs/edl_hw3/lib/python3.11/site-packages/huggingface_hub/__init__.py", line 332, in __getattr__
    submod = importlib.import_module(submod_path)
             ^^^^^^^^^^^^^^^^^^^^^^^^^^^^^^^^^^^^
  File "/uufs/chpc.utah.edu/common/home/u1419540/miniconda3/envs/edl_hw3/lib/python3.11/importlib/__init__.py", line 126, in import_module
    return _bootstrap._gcd_import(name[level:], package, level)
           ^^^^^^^^^^^^^^^^^^^^^^^^^^^^^^^^^^^^^^^^^^^^^^^^^^^^
  File "/uufs/chpc.utah.edu/common/home/u1419540/miniconda3/envs/edl_hw3/lib/python3.11/site-packages/huggingface_hub/repocard.py", line 6, in <module>
    import requests
  File "/uufs/chpc.utah.edu/common/home/u1419540/miniconda3/envs/edl_hw3/lib/python3.11/site-packages/requests/__init__.py", line 45, in <module>
    from .exceptions import RequestsDependencyWarning
  File "/uufs/chpc.utah.edu/common/home/u1419540/miniconda3/envs/edl_hw3/lib/python3.11/site-packages/requests/exceptions.py", line 9, in <module>
    from .compat import JSONDecodeError as CompatJSONDecodeError
  File "/uufs/chpc.utah.edu/common/home/u1419540/miniconda3/envs/edl_hw3/lib/python3.11/site-packages/requests/compat.py", line 13, in <module>
    import charset_normalizer as chardet
  File "/uufs/chpc.utah.edu/common/home/u1419540/miniconda3/envs/edl_hw3/lib/python3.11/site-packages/charset_normalizer/__init__.py", line 24, in <module>
    from .api import from_bytes, from_fp, from_path, is_binary
  File "/uufs/chpc.utah.edu/common/home/u1419540/miniconda3/envs/edl_hw3/lib/python3.11/site-packages/charset_normalizer/api.py", line 5, in <module>
    from .cd import (
  File "/uufs/chpc.utah.edu/common/home/u1419540/miniconda3/envs/edl_hw3/lib/python3.11/site-packages/charset_normalizer/cd.py", line 14, in <module>
    from .md import is_suspiciously_successive_range
  File "charset_normalizer/md.py", line 10, in <module>
ImportError: cannot import name 'is_ascii' from 'charset_normalizer.utils' (/uufs/chpc.utah.edu/common/home/u1419540/miniconda3/envs/edl_hw3/lib/python3.11/site-packages/charset_normalizer/utils.py)
